Workbook

Sheet Attendance Tracker
A1: Name | B1: Month | C1: Contact | D1: Group/ Department | E1: Actual Days Present | F1: Total Days Present | G1: Attendance Percentage | H1: Attendance Requirement Met? (>=80%)
A2: Attendee 1 | B2: 45474 | C2: =VLOOKUP(Table13[[#This Row],[Name]],List1_ContactInfo!A2:$B$58,2,0) -> attendee1@company.com | D2: =VLOOKUP(Table13[[#This Row],[Name]],List2_Department!$A$2:$B$51,2,0) -> Marketing | E2: =SUMIF(Table1[Name],Table1[[#This Row],[Name]],Table1[Attendance Value]) -> 2 | F2: =DATE(2024,7,5) - DATE(2024,7,1) + 1 -> 5 | G2: =IF(Table13[[#This Row],[Total Days Present]] <> 0, Table13[[#This Row],[Actual Days Present]] / Table13[[#This Row],[Total Days Present]], 0) -> 0.4 | H2: =IF(Table13[[#This Row],[Attendance Percentage]]>=0.8,"Met","Not Met") -> Not Met | K2: Attendance Requirement Met? (>=80% ) | L2: (All)
A3: Attendee 2 | B3: 45474 | C3: =VLOOKUP(Table13[[#This Row],[Name]],List1_ContactInfo!A3:$B$58,2,0) -> attendee2@company.com | D3: =VLOOKUP(Table13[[#This Row],[Name]],List2_Department!$A$2:$B$51,2,0) -> Sales | E3: =SUMIF(Table1[Name],Table1[[#This Row],[Name]],Table1[Attendance Value]) -> 3 | F3: =DATE(2024,7,5) - DATE(2024,7,1) + 1 -> 5 | G3: =IF(Table13[[#This Row],[Total Days Present]] <> 0, Table13[[#This Row],[Actual Days Present]] / Table13[[#This Row],[Total Days Present]], 0) -> 0.6 | H3: =IF(Table13[[#This Row],[Attendance Percentage]]>=0.8,"Met","Not Met") -> Not Met | K3: Actual Days Present | L3: (All)
A4: Attendee 3 | B4: 45474 | C4: =VLOOKUP(Table13[[#This Row],[Name]],List1_ContactInfo!A4:$B$58,2,0) -> attendee3@company.com | D4: =VLOOKUP(Table13[[#This Row],[Name]],List2_Department!$A$2:$B$51,2,0) -> HR | E4: =SUMIF(Table1[Name],Table1[[#This Row],[Name]],Table1[Attendance Value]) -> 2 | F4: =DATE(2024,7,5) - DATE(2024,7,1) + 1 -> 5 | G4: =IF(Table13[[#This Row],[Total Days Present]] <> 0, Table13[[#This Row],[Actual Days Present]] / Table13[[#This Row],[Total Days Present]], 0) -> 0.4 | H4: =IF(Table13[[#This Row],[Attendance Percentage]]>=0.8,"Met","Not Met") -> Not Met | N4: Dept Attendance %
A5: Attendee 4 | B5: 45474 | C5: =VLOOKUP(Table13[[#This Row],[Name]],List1_ContactInfo!A5:$B$58,2,0) -> attendee4@company.com | D5: =VLOOKUP(Table13[[#This Row],[Name]],List2_Department!$A$2:$B$51,2,0) -> IT | E5: =SUMIF(Table1[Name],Table1[[#This Row],[Name]],Table1[Attendance Value]) -> 2 | F5: =DATE(2024,7,5) - DATE(2024,7,1) + 1 -> 5 | G5: =IF(Table13[[#This Row],[Total Days Present]] <> 0, Table13[[#This Row],[Actual Days Present]] / Table13[[#This Row],[Total Days Present]], 0) -> 0.4 | H5: =IF(Table13[[#This Row],[Attendance Percentage]]>=0.8,"Met","Not Met") -> Not Met | K5: Name / Department | L5: Attendance % | N5: Department | O5: Avg Attendance %
A6: Attendee 5 | B6: 45474 | C6: =VLOOKUP(Table13[[#This Row],[Name]],List1_ContactInfo!A6:$B$58,2,0) -> attendee5@company.com | D6: =VLOOKUP(Table13[[#This Row],[Name]],List2_Department!$A$2:$B$51,2,0) -> Finance | E6: =SUMIF(Table1[Name],Table1[[#This Row],[Name]],Table1[Attendance Value]) -> 3 | F6: =DATE(2024,7,5) - DATE(2024,7,1) + 1 -> 5 | G6: =IF(Table13[[#This Row],[Total Days Present]] <> 0, Table13[[#This Row],[Actual Days Present]] / Table13[[#This Row],[Total Days Present]], 0) -> 0.6 | H6: =IF(Table13[[#This Row],[Attendance Percentage]]>=0.8,"Met","Not Met") -> Not Met | K6: Finance | N6: Finance | O6: 0.48
A7: Attendee 6 | B7: 45474 | C7: =VLOOKUP(Table13[[#This Row],[Name]],List1_ContactInfo!A7:$B$58,2,0) -> attendee6@company.com | D7: =VLOOKUP(Table13[[#This Row],[Name]],List2_Department!$A$2:$B$51,2,0) -> Marketing | E7: =SUMIF(Table1[Name],Table1[[#This Row],[Name]],Table1[Attendance Value]) -> 3 | F7: =DATE(2024,7,5) - DATE(2024,7,1) + 1 -> 5 | G7: =IF(Table13[[#This Row],[Total Days Present]] <> 0, Table13[[#This Row],[Actual Days Present]] / Table13[[#This Row],[Total Days Present]], 0) -> 0.6 | H7: =IF(Table13[[#This Row],[Attendance Percentage]]>=0.8,"Met","Not Met") -> Not Met | K7: Attendee 10 | L7: 0.4 | N7: HR | O7: 0.48
A8: Attendee 7 | B8: 45474 | C8: =VLOOKUP(Table13[[#This Row],[Name]],List1_ContactInfo!A8:$B$58,2,0) -> attendee7@company.com | D8: =VLOOKUP(Table13[[#This Row],[Name]],List2_Department!$A$2:$B$51,2,0) -> Sales | E8: =SUMIF(Table1[Name],Table1[[#This Row],[Name]],Table1[Attendance Value]) -> 4 | F8: =DATE(2024,7,5) - DATE(2024,7,1) + 1 -> 5 | G8: =IF(Table13[[#This Row],[Total Days Present]] <> 0, Table13[[#This Row],[Actual Days Present]] / Table13[[#This Row],[Total Days Present]], 0) -> 0.8 | H8: =IF(Table13[[#This Row],[Attendance Percentage]]>=0.8,"Met","Not Met") -> Met | K8: Attendee 15 | L8: 0.6 | N8: IT | O8: 0.54
A9: Attendee 8 | B9: 45474 | C9: =VLOOKUP(Table13[[#This Row],[Name]],List1_ContactInfo!A9:$B$58,2,0) -> attendee8@company.com | D9: =VLOOKUP(Table13[[#This Row],[Name]],List2_Department!$A$2:$B$51,2,0) -> HR | E9: =SUMIF(Table1[Name],Table1[[#This Row],[Name]],Table1[Attendance Value]) -> 3 | F9: =DATE(2024,7,5) - DATE(2024,7,1) + 1 -> 5 | G9: =IF(Table13[[#This Row],[Total Days Present]] <> 0, Table13[[#This Row],[Actual Days Present]] / Table13[[#This Row],[Total Days Present]], 0) -> 0.6 | H9: =IF(Table13[[#This Row],[Attendance Percentage]]>=0.8,"Met","Not Met") -> Not Met | K9: Attendee 20 | L9: 0.4 | N9: Marketing | O9: 0.52
A10: Attendee 9 | B10: 45474 | C10: =VLOOKUP(Table13[[#This Row],[Name]],List1_ContactInfo!A10:$B$58,2,0) -> attendee9@company.com | D10: =VLOOKUP(Table13[[#This Row],[Name]],List2_Department!$A$2:$B$51,2,0) -> IT | E10: =SUMIF(Table1[Name],Table1[[#This Row],[Name]],Table1[Attendance Value]) -> 4 | F10: =DATE(2024,7,5) - DATE(2024,7,1) + 1 -> 5 | G10: =IF(Table13[[#This Row],[Total Days Present]] <> 0, Table13[[#This Row],[Actual Days Present]] / Table13[[#This Row],[Total Days Present]], 0) -> 0.8 | H10: =IF(Table13[[#This Row],[Attendance Percentage]]>=0.8,"Met","Not Met") -> Met | K10: Attendee 25 | L10: 0.4 | N10: Sales | O10: 0.52
A11: Attendee 10 | B11: 45474 | C11: =VLOOKUP(Table13[[#This Row],[Name]],List1_ContactInfo!A11:$B$58,2,0) -> attendee10@company.com | D11: =VLOOKUP(Table13[[#This Row],[Name]],List2_Department!$A$2:$B$51,2,0) -> Finance | E11: =SUMIF(Table1[Name],Table1[[#This Row],[Name]],Table1[Attendance Value]) -> 2 | F11: =DATE(2024,7,5) - DATE(2024,7,1) + 1 -> 5 | G11: =IF(Table13[[#This Row],[Total Days Present]] <> 0, Table13[[#This Row],[Actual Days Present]] / Table13[[#This Row],[Total Days Present]], 0) -> 0.4 | H11: =IF(Table13[[#This Row],[Attendance Percentage]]>=0.8,"Met","Not Met") -> Not Met | K11: Attendee 30 | L11: 0.8
A12: Attendee 11 | B12: 45474 | C12: =VLOOKUP(Table13[[#This Row],[Name]],List1_ContactInfo!A12:$B$58,2,0) -> attendee11@company.com | D12: =VLOOKUP(Table13[[#This Row],[Name]],List2_Department!$A$2:$B$51,2,0) -> Marketing | E12: =SUMIF(Table1[Name],Table1[[#This Row],[Name]],Table1[Attendance Value]) -> 3 | F12: =DATE(2024,7,5) - DATE(2024,7,1) + 1 -> 5 | G12: =IF(Table13[[#This Row],[Total Days Present]] <> 0, Table13[[#This Row],[Actual Days Present]] / Table13[[#This Row],[Total Days Present]], 0) -> 0.6 | H12: =IF(Table13[[#This Row],[Attendance Percentage]]>=0.8,"Met","Not Met") -> Not Met | K12: Attendee 35 | L12: 0.6
A13: Attendee 12 | B13: 45474 | C13: =VLOOKUP(Table13[[#This Row],[Name]],List1_ContactInfo!A13:$B$58,2,0) -> attendee12@company.com | D13: =VLOOKUP(Table13[[#This Row],[Name]],List2_Department!$A$2:$B$51,2,0) -> Sales | E13: =SUMIF(Table1[Name],Table1[[#This Row],[Name]],Table1[Attendance Value]) -> 0 | F13: =DATE(2024,7,5) - DATE(2024,7,1) + 1 -> 5 | G13: =IF(Table13[[#This Row],[Total Days Present]] <> 0, Table13[[#This Row],[Actual Days Present]] / Table13[[#This Row],[Total Days Present]], 0) -> 0 | H13: =IF(Table13[[#This Row],[Attendance Percentage]]>=0.8,"Met","Not Met") -> Not Met | K13: Attendee 40 | L13: 0.2 | N13: Person with Highest Attendance
A14: Attendee 13 | B14: 45474 | C14: =VLOOKUP(Table13[[#This Row],[Name]],List1_ContactInfo!A14:$B$58,2,0) -> attendee13@company.com | D14: =VLOOKUP(Table13[[#This Row],[Name]],List2_Department!$A$2:$B$51,2,0) -> HR | E14: =SUMIF(Table1[Name],Table1[[#This Row],[Name]],Table1[Attendance Value]) -> 3 | F14: =DATE(2024,7,5) - DATE(2024,7,1) + 1 -> 5 | G14: =IF(Table13[[#This Row],[Total Days Present]] <> 0, Table13[[#This Row],[Actual Days Present]] / Table13[[#This Row],[Total Days Present]], 0) -> 0.6 | H14: =IF(Table13[[#This Row],[Attendance Percentage]]>=0.8,"Met","Not Met") -> Not Met | K14: Attendee 45 | L14: 0.6 | N14: Name / Department | O14: Attendance %
A15: Attendee 14 | B15: 45474 | C15: =VLOOKUP(Table13[[#This Row],[Name]],List1_ContactInfo!A15:$B$58,2,0) -> attendee14@company.com | D15: =VLOOKUP(Table13[[#This Row],[Name]],List2_Department!$A$2:$B$51,2,0) -> IT | E15: =SUMIF(Table1[Name],Table1[[#This Row],[Name]],Table1[Attendance Value]) -> 3 | F15: =DATE(2024,7,5) - DATE(2024,7,1) + 1 -> 5 | G15: =IF(Table13[[#This Row],[Total Days Present]] <> 0, Table13[[#This Row],[Actual Days Present]] / Table13[[#This Row],[Total Days Present]], 0) -> 0.6 | H15: =IF(Table13[[#This Row],[Attendance Percentage]]>=0.8,"Met","Not Met") -> Not Met | K15: Attendee 5 | L15: 0.6 | N15: HR
A16: Attendee 15 | B16: 45474 | C16: =VLOOKUP(Table13[[#This Row],[Name]],List1_ContactInfo!A16:$B$58,2,0) -> attendee15@company.com | D16: =VLOOKUP(Table13[[#This Row],[Name]],List2_Department!$A$2:$B$51,2,0) -> Finance | E16: =SUMIF(Table1[Name],Table1[[#This Row],[Name]],Table1[Attendance Value]) -> 3 | F16: =DATE(2024,7,5) - DATE(2024,7,1) + 1 -> 5 | G16: =IF(Table13[[#This Row],[Total Days Present]] <> 0, Table13[[#This Row],[Actual Days Present]] / Table13[[#This Row],[Total Days Present]], 0) -> 0.6 | H16: =IF(Table13[[#This Row],[Attendance Percentage]]>=0.8,"Met","Not Met") -> Not Met | K16: Attendee 50 | L16: 0.2 | N16: Attendee 33 | O16: 1
A17: Attendee 16 | B17: 45474 | C17: =VLOOKUP(Table13[[#This Row],[Name]],List1_ContactInfo!A17:$B$58,2,0) -> attendee16@company.com | D17: =VLOOKUP(Table13[[#This Row],[Name]],List2_Department!$A$2:$B$51,2,0) -> Marketing | E17: =SUMIF(Table1[Name],Table1[[#This Row],[Name]],Table1[Attendance Value]) -> 2 | F17: =DATE(2024,7,5) - DATE(2024,7,1) + 1 -> 5 | G17: =IF(Table13[[#This Row],[Total Days Present]] <> 0, Table13[[#This Row],[Actual Days Present]] / Table13[[#This Row],[Total Days Present]], 0) -> 0.4 | H17: =IF(Table13[[#This Row],[Attendance Percentage]]>=0.8,"Met","Not Met") -> Not Met | K17: HR
A18: Attendee 17 | B18: 45474 | C18: =VLOOKUP(Table13[[#This Row],[Name]],List1_ContactInfo!A18:$B$58,2,0) -> attendee17@company.com | D18: =VLOOKUP(Table13[[#This Row],[Name]],List2_Department!$A$2:$B$51,2,0) -> Sales | E18: =SUMIF(Table1[Name],Table1[[#This Row],[Name]],Table1[Attendance Value]) -> 3 | F18: =DATE(2024,7,5) - DATE(2024,7,1) + 1 -> 5 | G18: =IF(Table13[[#This Row],[Total Days Present]] <> 0, Table13[[#This Row],[Actual Days Present]] / Table13[[#This Row],[Total Days Present]], 0) -> 0.6 | H18: =IF(Table13[[#This Row],[Attendance Percentage]]>=0.8,"Met","Not Met") -> Not Met | K18: Attendee 13 | L18: 0.6
A19: Attendee 18 | B19: 45474 | C19: =VLOOKUP(Table13[[#This Row],[Name]],List1_ContactInfo!A19:$B$58,2,0) -> attendee18@company.com | D19: =VLOOKUP(Table13[[#This Row],[Name]],List2_Department!$A$2:$B$51,2,0) -> HR | E19: =SUMIF(Table1[Name],Table1[[#This Row],[Name]],Table1[Attendance Value]) -> 3 | F19: =DATE(2024,7,5) - DATE(2024,7,1) + 1 -> 5 | G19: =IF(Table13[[#This Row],[Total Days Present]] <> 0, Table13[[#This Row],[Actual Days Present]] / Table13[[#This Row],[Total Days Present]], 0) -> 0.6 | H19: =IF(Table13[[#This Row],[Attendance Percentage]]>=0.8,"Met","Not Met") -> Not Met | K19: Attendee 18 | L19: 0.6 | N19: % of Individuals with Attendance >=80% | O19: {=SUMPRODUCT(--(Table13[Attendance Requirement Met? (>=80%)]="Met"))/ROWS(Table13[Attendance Requirement Met? (>=80%)])} -> 0.18
A20: Attendee 19 | B20: 45474 | C20: =VLOOKUP(Table13[[#This Row],[Name]],List1_ContactInfo!A20:$B$58,2,0) -> attendee19@company.com | D20: =VLOOKUP(Table13[[#This Row],[Name]],List2_Department!$A$2:$B$51,2,0) -> IT | E20: =SUMIF(Table1[Name],Table1[[#This Row],[Name]],Table1[Attendance Value]) -> 3 | F20: =DATE(2024,7,5) - DATE(2024,7,1) + 1 -> 5 | G20: =IF(Table13[[#This Row],[Total Days Present]] <> 0, Table13[[#This Row],[Actual Days Present]] / Table13[[#This Row],[Total Days Present]], 0) -> 0.6 | H20: =IF(Table13[[#This Row],[Attendance Percentage]]>=0.8,"Met","Not Met") -> Not Met | K20: Attendee 23 | L20: 0.6
A21: Attendee 20 | B21: 45474 | C21: =VLOOKUP(Table13[[#This Row],[Name]],List1_ContactInfo!A21:$B$58,2,0) -> attendee20@company.com | D21: =VLOOKUP(Table13[[#This Row],[Name]],List2_Department!$A$2:$B$51,2,0) -> Finance | E21: =SUMIF(Table1[Name],Table1[[#This Row],[Name]],Table1[Attendance Value]) -> 2 | F21: =DATE(2024,7,5) - DATE(2024,7,1) + 1 -> 5 | G21: =IF(Table13[[#This Row],[Total Days Present]] <> 0, Table13[[#This Row],[Actual Days Present]] / Table13[[#This Row],[Total Days Present]], 0) -> 0.4 | H21: =IF(Table13[[#This Row],[Attendance Percentage]]>=0.8,"Met","Not Met") -> Not Met | K21: Attendee 28 | L21: 0
A22: Attendee 21 | B22: 45474 | C22: =VLOOKUP(Table13[[#This Row],[Name]],List1_ContactInfo!A25:$B$58,2,0) -> attendee21@company.com | D22: =VLOOKUP(Table13[[#This Row],[Name]],List2_Department!$A$2:$B$51,2,0) -> Marketing | E22: =SUMIF(Table1[Name],Table1[[#This Row],[Name]],Table1[Attendance Value]) -> 3 | F22: =DATE(2024,7,5) - DATE(2024,7,1) + 1 -> 5 | G22: =IF(Table13[[#This Row],[Total Days Present]] <> 0, Table13[[#This Row],[Actual Days Present]] / Table13[[#This Row],[Total Days Present]], 0) -> 0.6 | H22: =IF(Table13[[#This Row],[Attendance Percentage]]>=0.8,"Met","Not Met") -> Not Met | K22: Attendee 3 | L22: 0.4
A23: Attendee 22 | B23: 45474 | C23: =VLOOKUP(Table13[[#This Row],[Name]],List1_ContactInfo!A26:$B$58,2,0) -> attendee22@company.com | D23: =VLOOKUP(Table13[[#This Row],[Name]],List2_Department!$A$2:$B$51,2,0) -> Sales | E23: =SUMIF(Table1[Name],Table1[[#This Row],[Name]],Table1[Attendance Value]) -> 1 | F23: =DATE(2024,7,5) - DATE(2024,7,1) + 1 -> 5 | G23: =IF(Table13[[#This Row],[Total Days Present]] <> 0, Table13[[#This Row],[Actual Days Present]] / Table13[[#This Row],[Total Days Present]], 0) -> 0.2 | H23: =IF(Table13[[#This Row],[Attendance Percentage]]>=0.8,"Met","Not Met") -> Not Met | K23: Attendee 33 | L23: 1 | N23: Actual Days Present | O23: 1
A24: Attendee 23 | B24: 45474 | C24: =VLOOKUP(Table13[[#This Row],[Name]],List1_ContactInfo!A27:$B$58,2,0) -> attendee23@company.com | D24: =VLOOKUP(Table13[[#This Row],[Name]],List2_Department!$A$2:$B$51,2,0) -> HR | E24: =SUMIF(Table1[Name],Table1[[#This Row],[Name]],Table1[Attendance Value]) -> 3 | F24: =DATE(2024,7,5) - DATE(2024,7,1) + 1 -> 5 | G24: =IF(Table13[[#This Row],[Total Days Present]] <> 0, Table13[[#This Row],[Actual Days Present]] / Table13[[#This Row],[Total Days Present]], 0) -> 0.6 | H24: =IF(Table13[[#This Row],[Attendance Percentage]]>=0.8,"Met","Not Met") -> Not Met | K24: Attendee 38 | L24: 0.6 | N24: Name / Department | O24: Attendance %
A25: Attendee 24 | B25: 45474 | C25: =VLOOKUP(Table13[[#This Row],[Name]],List1_ContactInfo!A28:$B$58,2,0) -> attendee24@company.com | D25: =VLOOKUP(Table13[[#This Row],[Name]],List2_Department!$A$2:$B$51,2,0) -> IT | E25: =SUMIF(Table1[Name],Table1[[#This Row],[Name]],Table1[Attendance Value]) -> 2 | F25: =DATE(2024,7,5) - DATE(2024,7,1) + 1 -> 5 | G25: =IF(Table13[[#This Row],[Total Days Present]] <> 0, Table13[[#This Row],[Actual Days Present]] / Table13[[#This Row],[Total Days Present]], 0) -> 0.4 | H25: =IF(Table13[[#This Row],[Attendance Percentage]]>=0.8,"Met","Not Met") -> Not Met | K25: Attendee 43 | L25: 0.4 | N25: Finance
A26: Attendee 25 | B26: 45474 | C26: =VLOOKUP(Table13[[#This Row],[Name]],List1_ContactInfo!A29:$B$58,2,0) -> attendee25@company.com | D26: =VLOOKUP(Table13[[#This Row],[Name]],List2_Department!$A$2:$B$51,2,0) -> Finance | E26: =SUMIF(Table1[Name],Table1[[#This Row],[Name]],Table1[Attendance Value]) -> 2 | F26: =DATE(2024,7,5) - DATE(2024,7,1) + 1 -> 5 | G26: =IF(Table13[[#This Row],[Total Days Present]] <> 0, Table13[[#This Row],[Actual Days Present]] / Table13[[#This Row],[Total Days Present]], 0) -> 0.4 | H26: =IF(Table13[[#This Row],[Attendance Percentage]]>=0.8,"Met","Not Met") -> Not Met | K26: Attendee 48 | L26: 0 | N26: Attendee 40 | O26: 0.2
A27: Attendee 26 | B27: 45474 | C27: =VLOOKUP(Table13[[#This Row],[Name]],List1_ContactInfo!A30:$B$58,2,0) -> attendee26@company.com | D27: =VLOOKUP(Table13[[#This Row],[Name]],List2_Department!$A$2:$B$51,2,0) -> Marketing | E27: =SUMIF(Table1[Name],Table1[[#This Row],[Name]],Table1[Attendance Value]) -> 2 | F27: =DATE(2024,7,5) - DATE(2024,7,1) + 1 -> 5 | G27: =IF(Table13[[#This Row],[Total Days Present]] <> 0, Table13[[#This Row],[Actual Days Present]] / Table13[[#This Row],[Total Days Present]], 0) -> 0.4 | H27: =IF(Table13[[#This Row],[Attendance Percentage]]>=0.8,"Met","Not Met") -> Not Met | K27: Attendee 8 | L27: 0.6 | N27: Attendee 50 | O27: 0.2
A28: Attendee 27 | B28: 45474 | C28: =VLOOKUP(Table13[[#This Row],[Name]],List1_ContactInfo!A31:$B$58,2,0) -> attendee27@company.com | D28: =VLOOKUP(Table13[[#This Row],[Name]],List2_Department!$A$2:$B$51,2,0) -> Sales | E28: =SUMIF(Table1[Name],Table1[[#This Row],[Name]],Table1[Attendance Value]) -> 4 | F28: =DATE(2024,7,5) - DATE(2024,7,1) + 1 -> 5 | G28: =IF(Table13[[#This Row],[Total Days Present]] <> 0, Table13[[#This Row],[Actual Days Present]] / Table13[[#This Row],[Total Days Present]], 0) -> 0.8 | H28: =IF(Table13[[#This Row],[Attendance Percentage]]>=0.8,"Met","Not Met") -> Met | K28: IT | N28: Sales
A29: Attendee 28 | B29: 45474 | C29: =VLOOKUP(Table13[[#This Row],[Name]],List1_ContactInfo!A32:$B$58,2,0) -> attendee28@company.com | D29: =VLOOKUP(Table13[[#This Row],[Name]],List2_Department!$A$2:$B$51,2,0) -> HR | E29: =SUMIF(Table1[Name],Table1[[#This Row],[Name]],Table1[Attendance Value]) -> 0 | F29: =DATE(2024,7,5) - DATE(2024,7,1) + 1 -> 5 | G29: =IF(Table13[[#This Row],[Total Days Present]] <> 0, Table13[[#This Row],[Actual Days Present]] / Table13[[#This Row],[Total Days Present]], 0) -> 0 | H29: =IF(Table13[[#This Row],[Attendance Percentage]]>=0.8,"Met","Not Met") -> Not Met | K29: Attendee 14 | L29: 0.6 | N29: Attendee 22 | O29: 0.2
A30: Attendee 29 | B30: 45474 | C30: =VLOOKUP(Table13[[#This Row],[Name]],List1_ContactInfo!A33:$B$58,2,0) -> attendee29@company.com | D30: =VLOOKUP(Table13[[#This Row],[Name]],List2_Department!$A$2:$B$51,2,0) -> IT | E30: =SUMIF(Table1[Name],Table1[[#This Row],[Name]],Table1[Attendance Value]) -> 3 | F30: =DATE(2024,7,5) - DATE(2024,7,1) + 1 -> 5 | G30: =IF(Table13[[#This Row],[Total Days Present]] <> 0, Table13[[#This Row],[Actual Days Present]] / Table13[[#This Row],[Total Days Present]], 0) -> 0.6 | H30: =IF(Table13[[#This Row],[Attendance Percentage]]>=0.8,"Met","Not Met") -> Not Met | K30: Attendee 19 | L30: 0.6 | N30: Attendee 42 | O30: 0.2
A31: Attendee 30 | B31: 45474 | C31: =VLOOKUP(Table13[[#This Row],[Name]],List1_ContactInfo!A34:$B$58,2,0) -> attendee30@company.com | D31: =VLOOKUP(Table13[[#This Row],[Name]],List2_Department!$A$2:$B$51,2,0) -> Finance | E31: =SUMIF(Table1[Name],Table1[[#This Row],[Name]],Table1[Attendance Value]) -> 4 | F31: =DATE(2024,7,5) - DATE(2024,7,1) + 1 -> 5 | G31: =IF(Table13[[#This Row],[Total Days Present]] <> 0, Table13[[#This Row],[Actual Days Present]] / Table13[[#This Row],[Total Days Present]], 0) -> 0.8 | H31: =IF(Table13[[#This Row],[Attendance Percentage]]>=0.8,"Met","Not Met") -> Met | K31: Attendee 24 | L31: 0.4
A32: Attendee 31 | B32: 45474 | C32: =VLOOKUP(Table13[[#This Row],[Name]],List1_ContactInfo!A35:$B$58,2,0) -> attendee31@company.com | D32: =VLOOKUP(Table13[[#This Row],[Name]],List2_Department!$A$2:$B$51,2,0) -> Marketing | E32: =SUMIF(Table1[Name],Table1[[#This Row],[Name]],Table1[Attendance Value]) -> 2 | F32: =DATE(2024,7,5) - DATE(2024,7,1) + 1 -> 5 | G32: =IF(Table13[[#This Row],[Total Days Present]] <> 0, Table13[[#This Row],[Actual Days Present]] / Table13[[#This Row],[Total Days Present]], 0) -> 0.4 | H32: =IF(Table13[[#This Row],[Attendance Percentage]]>=0.8,"Met","Not Met") -> Not Met | K32: Attendee 29 | L32: 0.6
A33: Attendee 32 | B33: 45474 | C33: =VLOOKUP(Table13[[#This Row],[Name]],List1_ContactInfo!A36:$B$58,2,0) -> attendee32@company.com | D33: =VLOOKUP(Table13[[#This Row],[Name]],List2_Department!$A$2:$B$51,2,0) -> Sales | E33: =SUMIF(Table1[Name],Table1[[#This Row],[Name]],Table1[Attendance Value]) -> 2 | F33: =DATE(2024,7,5) - DATE(2024,7,1) + 1 -> 5 | G33: =IF(Table13[[#This Row],[Total Days Present]] <> 0, Table13[[#This Row],[Actual Days Present]] / Table13[[#This Row],[Total Days Present]], 0) -> 0.4 | H33: =IF(Table13[[#This Row],[Attendance Percentage]]>=0.8,"Met","Not Met") -> Not Met | K33: Attendee 34 | L33: 0.4
A34: Attendee 33 | B34: 45474 | C34: =VLOOKUP(Table13[[#This Row],[Name]],List1_ContactInfo!A37:$B$58,2,0) -> attendee33@company.com | D34: =VLOOKUP(Table13[[#This Row],[Name]],List2_Department!$A$2:$B$51,2,0) -> HR | E34: =SUMIF(Table1[Name],Table1[[#This Row],[Name]],Table1[Attendance Value]) -> 5 | F34: =DATE(2024,7,5) - DATE(2024,7,1) + 1 -> 5 | G34: =IF(Table13[[#This Row],[Total Days Present]] <> 0, Table13[[#This Row],[Actual Days Present]] / Table13[[#This Row],[Total Days Present]], 0) -> 1 | H34: =IF(Table13[[#This Row],[Attendance Percentage]]>=0.8,"Met","Not Met") -> Met | K34: Attendee 39 | L34: 0.8
A35: Attendee 34 | B35: 45474 | C35: =VLOOKUP(Table13[[#This Row],[Name]],List1_ContactInfo!A38:$B$58,2,0) -> attendee34@company.com | D35: =VLOOKUP(Table13[[#This Row],[Name]],List2_Department!$A$2:$B$51,2,0) -> IT | E35: =SUMIF(Table1[Name],Table1[[#This Row],[Name]],Table1[Attendance Value]) -> 2 | F35: =DATE(2024,7,5) - DATE(2024,7,1) + 1 -> 5 | G35: =IF(Table13[[#This Row],[Total Days Present]] <> 0, Table13[[#This Row],[Actual Days Present]] / Table13[[#This Row],[Total Days Present]], 0) -> 0.4 | H35: =IF(Table13[[#This Row],[Attendance Percentage]]>=0.8,"Met","Not Met") -> Not Met | K35: Attendee 4 | L35: 0.4
A36: Attendee 35 | B36: 45474 | C36: =VLOOKUP(Table13[[#This Row],[Name]],List1_ContactInfo!A39:$B$58,2,0) -> attendee35@company.com | D36: =VLOOKUP(Table13[[#This Row],[Name]],List2_Department!$A$2:$B$51,2,0) -> Finance | E36: =SUMIF(Table1[Name],Table1[[#This Row],[Name]],Table1[Attendance Value]) -> 3 | F36: =DATE(2024,7,5) - DATE(2024,7,1) + 1 -> 5 | G36: =IF(Table13[[#This Row],[Total Days Present]] <> 0, Table13[[#This Row],[Actual Days Present]] / Table13[[#This Row],[Total Days Present]], 0) -> 0.6 | H36: =IF(Table13[[#This Row],[Attendance Percentage]]>=0.8,"Met","Not Met") -> Not Met | K36: Attendee 44 | L36: 0.4
A37: Attendee 36 | B37: 45474 | C37: =VLOOKUP(Table13[[#This Row],[Name]],List1_ContactInfo!A40:$B$58,2,0) -> attendee36@company.com | D37: =VLOOKUP(Table13[[#This Row],[Name]],List2_Department!$A$2:$B$51,2,0) -> Marketing | E37: =SUMIF(Table1[Name],Table1[[#This Row],[Name]],Table1[Attendance Value]) -> 3 | F37: =DATE(2024,7,5) - DATE(2024,7,1) + 1 -> 5 | G37: =IF(Table13[[#This Row],[Total Days Present]] <> 0, Table13[[#This Row],[Actual Days Present]] / Table13[[#This Row],[Total Days Present]], 0) -> 0.6 | H37: =IF(Table13[[#This Row],[Attendance Percentage]]>=0.8,"Met","Not Met") -> Not Met | K37: Attendee 49 | L37: 0.4
A38: Attendee 37 | B38: 45474 | C38: =VLOOKUP(Table13[[#This Row],[Name]],List1_ContactInfo!A41:$B$58,2,0) -> attendee37@company.com | D38: =VLOOKUP(Table13[[#This Row],[Name]],List2_Department!$A$2:$B$51,2,0) -> Sales | E38: =SUMIF(Table1[Name],Table1[[#This Row],[Name]],Table1[Attendance Value]) -> 4 | F38: =DATE(2024,7,5) - DATE(2024,7,1) + 1 -> 5 | G38: =IF(Table13[[#This Row],[Total Days Present]] <> 0, Table13[[#This Row],[Actual Days Present]] / Table13[[#This Row],[Total Days Present]], 0) -> 0.8 | H38: =IF(Table13[[#This Row],[Attendance Percentage]]>=0.8,"Met","Not Met") -> Met | K38: Attendee 9 | L38: 0.8
A39: Attendee 38 | B39: 45474 | C39: =VLOOKUP(Table13[[#This Row],[Name]],List1_ContactInfo!A42:$B$58,2,0) -> attendee38@company.com | D39: =VLOOKUP(Table13[[#This Row],[Name]],List2_Department!$A$2:$B$51,2,0) -> HR | E39: =SUMIF(Table1[Name],Table1[[#This Row],[Name]],Table1[Attendance Value]) -> 3 | F39: =DATE(2024,7,5) - DATE(2024,7,1) + 1 -> 5 | G39: =IF(Table13[[#This Row],[Total Days Present]] <> 0, Table13[[#This Row],[Actual Days Present]] / Table13[[#This Row],[Total Days Present]], 0) -> 0.6 | H39: =IF(Table13[[#This Row],[Attendance Percentage]]>=0.8,"Met","Not Met") -> Not Met | K39: Marketing | L39: 0.52
A40: Attendee 39 | B40: 45474 | C40: =VLOOKUP(Table13[[#This Row],[Name]],List1_ContactInfo!A43:$B$58,2,0) -> attendee39@company.com | D40: =VLOOKUP(Table13[[#This Row],[Name]],List2_Department!$A$2:$B$51,2,0) -> IT | E40: =SUMIF(Table1[Name],Table1[[#This Row],[Name]],Table1[Attendance Value]) -> 4 | F40: =DATE(2024,7,5) - DATE(2024,7,1) + 1 -> 5 | G40: =IF(Table13[[#This Row],[Total Days Present]] <> 0, Table13[[#This Row],[Actual Days Present]] / Table13[[#This Row],[Total Days Present]], 0) -> 0.8 | H40: =IF(Table13[[#This Row],[Attendance Percentage]]>=0.8,"Met","Not Met") -> Met | K40: Sales | L40: 0.52
...

Sheet List1_ContactInfo
A1: Name | B1: Email Address
A2: Attendee 1 | B2: attendee1@company.com
A3: Attendee 2 | B3: attendee2@company.com
A4: Attendee 3 | B4: attendee3@company.com
A5: Attendee 4 | B5: attendee4@company.com
A6: Attendee 5 | B6: attendee5@company.com
A7: Attendee 6 | B7: attendee6@company.com
A8: Attendee 7 | B8: attendee7@company.com
A9: Attendee 8 | B9: attendee8@company.com
A10: Attendee 9 | B10: attendee9@company.com
A11: Attendee 10 | B11: attendee10@company.com
A12: Attendee 11 | B12: attendee11@company.com
... A58: Attendee 50 | B58: attendee50@company.com

Sheet List2_Department
A1: Name | B1: Department | D1: Legend
A2: Attendee 1 | B2: Marketing | D2: Department | E2: Group
A3: Attendee 2 | B3: Sales | D3: Marketing | E3: A
A4: Attendee 3 | B4: HR | D4: Sales | E4: B
A5: Attendee 4 | B5: IT | D5: HR | E5: C
A6: Attendee 5 | B6: Finance | D6: IT | E6: D
A7: Attendee 6 | B7: Marketing | D7: Finance | E7: E
A8: Attendee 7 | B8: Sales
A9: Attendee 8 | B9: HR
A10: Attendee 9 | B10: IT
A11: Attendee 10 | B11: Finance
A12: Attendee 11 | B12: Marketing
A13: Attendee 12 | B13: Sales
A14: Attendee 13 | B14: HR
A15: Attendee 14 | B15: IT
A16: Attendee 15 | B16: Finance
A17: Attendee 16 | B17: Marketing
A18: Attendee 17 | B18: Sales
A19: Attendee 18 | B19: HR
... A51: Attendee 50 | B51: Finance

Sheet List3_Details
A1: Name | B1: Date | C1: Attended | D1: Attendance Status | E1: Attendance Value
A2: Attendee 1 | B2: 45474 | C2: Yes | D2: =IF(C2="Yes","Present","Absent") -> Present | E2: =IF(D2="Present",1,0) -> 1
A3: Attendee 2 | B3: 45474 | C3: No | D3: =IF(C3="Yes","Present","Absent") -> Absent | E3: =IF(D3="Present",1,0) -> 0
A4: Attendee 3 | B4: 45474 | C4: Yes | D4: =IF(C4="Yes","Present","Absent") -> Present | E4: =IF(D4="Present",1,0) -> 1 | H4: Attendance Count | I4: Attendance Status
A5: Attendee 4 | B5: 45474 | C5: No | D5: =IF(C5="Yes","Present","Absent") -> Absent | E5: =IF(D5="Present",1,0) -> 0 | H5: Date | I5: Present | J5: Total
A6: Attendee 5 | B6: 45474 | C6: Yes | D6: =IF(C6="Yes","Present","Absent") -> Present | E6: =IF(D6="Present",1,0) -> 1 | H6: 45474 | I6: 25 | J6: 25
A7: Attendee 6 | B7: 45474 | C7: No | D7: =IF(C7="Yes","Present","Absent") -> Absent | E7: =IF(D7="Present",1,0) -> 0 | H7: 45475 | I7: 25 | J7: 25
A8: Attendee 7 | B8: 45474 | C8: Yes | D8: =IF(C8="Yes","Present","Absent") -> Present | E8: =IF(D8="Present",1,0) -> 1 | H8: 45476 | I8: 24 | J8: 24
A9: Attendee 8 | B9: 45474 | C9: No | D9: =IF(C9="Yes","Present","Absent") -> Absent | E9: =IF(D9="Present",1,0) -> 0 | H9: 45477 | I9: 30 | J9: 30
A10: Attendee 9 | B10: 45474 | C10: Yes | D10: =IF(C10="Yes","Present","Absent") -> Present | E10: =IF(D10="Present",1,0) -> 1 | H10: 45478 | I10: 23 | J10: 23
A11: Attendee 10 | B11: 45474 | C11: No | D11: =IF(C11="Yes","Present","Absent") -> Absent | E11: =IF(D11="Present",1,0) -> 0
A12: Attendee 11 | B12: 45474 | C12: Yes | D12: =IF(C12="Yes","Present","Absent") -> Present | E12: =IF(D12="Present",1,0) -> 1
A13: Attendee 12 | B13: 45474 | C13: No | D13: =IF(C13="Yes","Present","Absent") -> Absent | E13: =IF(D13="Present",1,0) -> 0 | H13: Day Attendance %
A14: Attendee 13 | B14: 45474 | C14: Yes | D14: =IF(C14="Yes","Present","Absent") -> Present | E14: =IF(D14="Present",1,0) -> 1 | H14: Date | I14: Present | J14: Day Total | K14: Attendance %
A15: Attendee 14 | B15: 45474 | C15: No | D15: =IF(C15="Yes","Present","Absent") -> Absent | E15: =IF(D15="Present",1,0) -> 0 | H15: 45474 | I15: 25 | J15: 50 | K15: =I15/J15 -> 0.5
A16: Attendee 15 | B16: 45474 | C16: Yes | D16: =IF(C16="Yes","Present","Absent") -> Present | E16: =IF(D16="Present",1,0) -> 1 | H16: 45475 | I16: 25 | J16: 50 | K16: =I16/J16 -> 0.5
A17: Attendee 16 | B17: 45474 | C17: No | D17: =IF(C17="Yes","Present","Absent") -> Absent | E17: =IF(D17="Present",1,0) -> 0 | H17: 45476 | I17: 24 | J17: 50 | K17: =I17/J17 -> 0.48
A18: Attendee 17 | B18: 45474 | C18: Yes | D18: =IF(C18="Yes","Present","Absent") -> Present | E18: =IF(D18="Present",1,0) -> 1 | H18: 45477 | I18: 30 | J18: 50 | K18: =I18/J18 -> 0.6
A19: Attendee 18 | B19: 45474 | C19: No | D19: =IF(C19="Yes","Present","Absent") -> Absent | E19: =IF(D19="Present",1,0) -> 0 | H19: 45478 | I19: 23 | J19: 50 | K19: =I19/J19 -> 0.46
A20: Attendee 19 | B20: 45474 | C20: Yes | D20: =IF(C20="Yes","Present","Absent") -> Present | E20: =IF(D20="Present",1,0) -> 1
A21: Attendee 20 | B21: 45474 | C21: No | D21: =IF(C21="Yes","Present","Absent") -> Absent | E21: =IF(D21="Present",1,0) -> 0
A22: Attendee 21 | B22: 45474 | C22: Yes | D22: =IF(C22="Yes","Present","Absent") -> Present | E22: =IF(D22="Present",1,0) -> 1
A23: Attendee 22 | B23: 45474 | C23: No | D23: =IF(C23="Yes","Present","Absent") -> Absent | E23: =IF(D23="Present",1,0) -> 0
A24: Attendee 23 | B24: 45474 | C24: Yes | D24: =IF(C24="Yes","Present","Absent") -> Present | E24: =IF(D24="Present",1,0) -> 1
A25: Attendee 24 | B25: 45474 | C25: No | D25: =IF(C25="Yes","Present","Absent") -> Absent | E25: =IF(D25="Present",1,0) -> 0
A26: Attendee 25 | B26: 45474 | C26: Yes | D26: =IF(C26="Yes","Present","Absent") -> Present | E26: =IF(D26="Present",1,0) -> 1
A27: Attendee 26 | B27: 45474 | C27: No | D27: =IF(C27="Yes","Present","Absent") -> Absent | E27: =IF(D27="Present",1,0) -> 0
A28: Attendee 27 | B28: 45474 | C28: Yes | D28: =IF(C28="Yes","Present","Absent") -> Present | E28: =IF(D28="Present",1,0) -> 1
A29: Attendee 28 | B29: 45474 | C29: No | D29: =IF(C29="Yes","Present","Absent") -> Absent | E29: =IF(D29="Present",1,0) -> 0
A30: Attendee 29 | B30: 45474 | C30: Yes | D30: =IF(C30="Yes","Present","Absent") -> Present | E30: =IF(D30="Present",1,0) -> 1
A31: Attendee 30 | B31: 45474 | C31: No | D31: =IF(C31="Yes","Present","Absent") -> Absent | E31: =IF(D31="Present",1,0) -> 0
... A251: Attendee 50 | B251: 45478 | C251: No | D251: =IF(C251="Yes","Present","Absent") -> Absent | E251: =IF(D251="Present",1,0) -> 0
